test_delete_queue (__main__.TestExercice) ... FAIL
test_delete_stack (__main__.TestExercice) ... ERROR
test_reverse (__main__.TestExercice) ... ok
test_sort_queue (__main__.TestExercice) ... FAIL
test_sort_stack (__main__.TestExercice) ... FAIL
test_string_and_structs (__main__.TestExercice) ... ERROR

======================================================================
ERROR: test_delete_stack (__main__.TestExercice)
----------------------------------------------------------------------
Traceback (most recent call last):
  File "test_exercice.py", line 33, in test_delete_stack
    output = exercice.delete_nth_from_stack(lifo, len(lifo) - 1)
  File "/home/runner/work/c03_ch6_exercices-2-simonhache/c03_ch6_exercices-2-simonhache/exercice.py", line 19, in delete_nth_from_stack
    newData = [el for el,idx in enumerate(list(data)) if idx != position]
TypeError: 'Stack' object is not iterable

======================================================================
ERROR: test_string_and_structs (__main__.TestExercice)
----------------------------------------------------------------------
Traceback (most recent call last):
  File "test_exercice.py", line 91, in test_string_and_structs
    fifo.put_many("Yeet")
TypeError: put_many() missing 1 required positional argument: 'items'

======================================================================
FAIL: test_delete_queue (__main__.TestExercice)
----------------------------------------------------------------------
Traceback (most recent call last):
  File "test_exercice.py", line 53, in test_delete_queue
    'Mauvaise reponse'
AssertionError: [] != [1, 2, 3, 4, 5, 6, 7, 8, 9, 10, 11, 12, 13, 14, 15, 16, 17, 18, 19] : Mauvaise reponse

======================================================================
FAIL: test_sort_queue (__main__.TestExercice)
----------------------------------------------------------------------
Traceback (most recent call last):
  File "test_exercice.py", line 83, in test_sort_queue
    'Mauvaise reponse'
AssertionError: [] != [7, 210, 219, 330, 371, 380, 401, 412, 420[51 chars] 971] : Mauvaise reponse

======================================================================
FAIL: test_sort_stack (__main__.TestExercice)
----------------------------------------------------------------------
Traceback (most recent call last):
  File "test_exercice.py", line 68, in test_sort_stack
    'Mauvaise reponse'
AssertionError: [] != [35, 39, 99, 134, 246, 332, 338, 377, 409,[50 chars] 918] : Mauvaise reponse

----------------------------------------------------------------------
Ran 6 tests in 0.001s

FAILED (failures=3, errors=2)
